[2024-05-12T02:08:13.321+0000] {local_task_job_runner.py:120} INFO - ::group::Pre task execution logs
[2024-05-12T02:08:13.334+0000] {taskinstance.py:2076} INFO - Dependencies all met for dep_context=non-requeueable deps ti=<TaskInstance: tutorial_v2.second_task scheduled__2024-05-11T00:00:00+00:00 [queued]>
[2024-05-12T02:08:13.338+0000] {taskinstance.py:2076} INFO - Dependencies all met for dep_context=requeueable deps ti=<TaskInstance: tutorial_v2.second_task scheduled__2024-05-11T00:00:00+00:00 [queued]>
[2024-05-12T02:08:13.338+0000] {taskinstance.py:2306} INFO - Starting attempt 1 of 6
[2024-05-12T02:08:13.343+0000] {taskinstance.py:2330} INFO - Executing <Task(BashOperator): second_task> on 2024-05-11 00:00:00+00:00
[2024-05-12T02:08:13.346+0000] {standard_task_runner.py:90} INFO - Running: ['***', 'tasks', 'run', 'tutorial_v2', 'second_task', 'scheduled__2024-05-11T00:00:00+00:00', '--job-id', '6', '--raw', '--subdir', 'DAGS_FOLDER/our_first_dag.py', '--cfg-path', '/tmp/tmpp6p1ee51']
[2024-05-12T02:08:13.347+0000] {logging_mixin.py:188} WARNING - /home/***/.local/lib/python3.12/site-packages/***/task/task_runner/standard_task_runner.py:61 DeprecationWarning: This process (pid=985) is multi-threaded, use of fork() may lead to deadlocks in the child.
[2024-05-12T02:08:13.347+0000] {standard_task_runner.py:91} INFO - Job 6: Subtask second_task
[2024-05-12T02:08:13.348+0000] {standard_task_runner.py:63} INFO - Started process 986 to run task
[2024-05-12T02:08:13.366+0000] {task_command.py:426} INFO - Running <TaskInstance: tutorial_v2.second_task scheduled__2024-05-11T00:00:00+00:00 [running]> on host e768b7f5ee51
[2024-05-12T02:08:13.398+0000] {taskinstance.py:2648} INFO - Exporting env vars: AIRFLOW_CTX_DAG_OWNER='tony arianto' AIRFLOW_CTX_DAG_ID='tutorial_v2' AIRFLOW_CTX_TASK_ID='second_task' AIRFLOW_CTX_EXECUTION_DATE='2024-05-11T00:00:00+00:00' AIRFLOW_CTX_TRY_NUMBER='1' AIRFLOW_CTX_DAG_RUN_ID='scheduled__2024-05-11T00:00:00+00:00'
[2024-05-12T02:08:13.399+0000] {taskinstance.py:430} INFO - ::endgroup::
[2024-05-12T02:08:13.405+0000] {subprocess.py:63} INFO - Tmp dir root location: /tmp
[2024-05-12T02:08:13.406+0000] {subprocess.py:75} INFO - Running command: ['/usr/bin/bash', '-c', 'echo, Hai...ini task2 akan dijalankan setelah task1 !']
[2024-05-12T02:08:13.409+0000] {subprocess.py:86} INFO - Output:
[2024-05-12T02:08:13.410+0000] {subprocess.py:93} INFO - /usr/bin/bash: line 1: echo,: command not found
[2024-05-12T02:08:13.410+0000] {subprocess.py:97} INFO - Command exited with return code 127
[2024-05-12T02:08:13.411+0000] {taskinstance.py:441} INFO - ::group::Post task execution logs
[2024-05-12T02:08:13.415+0000] {taskinstance.py:2905} ERROR - Task failed with exception
Traceback (most recent call last):
  File "/home/airflow/.local/lib/python3.12/site-packages/airflow/models/taskinstance.py", line 465, in _execute_task
    result = _execute_callable(context=context, **execute_callable_kwargs)
             ^^^^^^^^^^^^^^^^^^^^^^^^^^^^^^^^^^^^^^^^^^^^^^^^^^^^^^^^^^^^^
  File "/home/airflow/.local/lib/python3.12/site-packages/airflow/models/taskinstance.py", line 432, in _execute_callable
    return execute_callable(context=context, **execute_callable_kwargs)
           ^^^^^^^^^^^^^^^^^^^^^^^^^^^^^^^^^^^^^^^^^^^^^^^^^^^^^^^^^^^^
  File "/home/airflow/.local/lib/python3.12/site-packages/airflow/models/baseoperator.py", line 400, in wrapper
    return func(self, *args, **kwargs)
           ^^^^^^^^^^^^^^^^^^^^^^^^^^^
  File "/home/airflow/.local/lib/python3.12/site-packages/airflow/operators/bash.py", line 243, in execute
    raise AirflowException(
airflow.exceptions.AirflowException: Bash command failed. The command returned a non-zero exit code 127.
[2024-05-12T02:08:13.417+0000] {taskinstance.py:1206} INFO - Marking task as UP_FOR_RETRY. dag_id=tutorial_v2, task_id=second_task, run_id=scheduled__2024-05-11T00:00:00+00:00, execution_date=20240511T000000, start_date=20240512T020813, end_date=20240512T020813
[2024-05-12T02:08:13.422+0000] {standard_task_runner.py:110} ERROR - Failed to execute job 6 for task second_task (Bash command failed. The command returned a non-zero exit code 127.; 986)
[2024-05-12T02:08:13.447+0000] {local_task_job_runner.py:240} INFO - Task exited with return code 1
[2024-05-12T02:08:13.454+0000] {taskinstance.py:3498} INFO - 0 downstream tasks scheduled from follow-on schedule check
[2024-05-12T02:08:13.455+0000] {local_task_job_runner.py:222} INFO - ::endgroup::
